<?xml version="1.0" ?>
<robot name="diff_bot" xmlns:xacro="http://www.ros.org/wiki/xacro">

<xacro:include filename="$(find diff_bot_description)/urdf/materials.xacro" />
<xacro:include filename="$(find diff_bot_description)/urdf/diff_bot.ros2_control.xacro" />
<xacro:include filename="$(find diff_bot_description)/urdf/diff_bot.gazebo" /> 

<link name="base_link">
  <inertial>
    <origin xyz="0.0003705884700577632 1.0604832058231093e-13 0.034681404539174294" rpy="0 0 0"/>
    <mass value="111.46600539799809"/>
    <inertia ixx="1.550497" iyy="2.385555" izz="3.842836" ixy="0.0" iyz="0.0" ixz="-0.00534"/>
  </inertial>
  <visual>
    <origin xyz="0 0 0" rpy="0 0 0"/>
    <geometry>
      <mesh filename="file://$(find diff_bot_description)/meshes/base_link.stl" scale="0.001 0.001 0.001"/>
    </geometry>
    <material name="silver"/>
  </visual>
  <collision>
    <origin xyz="0 0 0" rpy="0 0 0"/>
    <geometry>
      <mesh filename="file://$(find diff_bot_description)/meshes/base_link.stl" scale="0.001 0.001 0.001"/>
    </geometry>
  </collision>
</link>

<link name="right_wheel_1">
  <inertial>
    <origin xyz="1.6006640457533194e-13 -0.014999999999999986 0.0" rpy="0 0 0"/>
    <mass value="3.8656904903340568"/>
    <inertia ixx="0.006113" iyy="0.011645" izz="0.006113" ixy="0.0" iyz="0.0" ixz="-0.0"/>
  </inertial>
  <visual>
    <origin xyz="-0.2 -0.24 -0.035" rpy="0 0 0"/>
    <geometry>
      <mesh filename="file://$(find diff_bot_description)/meshes/right_wheel_1.stl" scale="0.001 0.001 0.001"/>
    </geometry>
    <material name="silver"/>
  </visual>
  <collision>
    <origin xyz="-0.2 -0.24 -0.035" rpy="0 0 0"/>
    <geometry>
      <mesh filename="file://$(find diff_bot_description)/meshes/right_wheel_1.stl" scale="0.001 0.001 0.001"/>
    </geometry>
  </collision>
</link>

<link name="left_wheel_1">
  <inertial>
    <origin xyz="1.6006640457533194e-13 0.014999999999999986 0.0" rpy="0 0 0"/>
    <mass value="3.8656904903340568"/>
    <inertia ixx="0.006113" iyy="0.011645" izz="0.006113" ixy="-0.0" iyz="0.0" ixz="-0.0"/>
  </inertial>
  <visual>
    <origin xyz="-0.2 0.24 -0.035" rpy="0 0 0"/>
    <geometry>
      <mesh filename="file://$(find diff_bot_description)/meshes/left_wheel_1.stl" scale="0.001 0.001 0.001"/>
    </geometry>
    <material name="silver"/>
  </visual>
  <collision>
    <origin xyz="-0.2 0.24 -0.035" rpy="0 0 0"/>
    <geometry>
      <mesh filename="file://$(find diff_bot_description)/meshes/left_wheel_1.stl" scale="0.001 0.001 0.001"/>
    </geometry>
  </collision>
</link>

<joint name="right_wheel_joint" type="continuous">
  <origin xyz="0.2 0.24 0.035" rpy="0 0 0"/>
  <parent link="base_link"/>
  <child link="right_wheel_1"/>
  <axis xyz="0.0 1.0 0.0"/>
</joint>

<joint name="left_wheel_joint" type="continuous">
  <origin xyz="0.2 -0.24 0.035" rpy="0 0 0"/>
  <parent link="base_link"/>
  <child link="left_wheel_1"/>
  <axis xyz="0.0 1.0 0.0"/>
</joint>

<link name="lidar_link">
  <inertial>
    <origin xyz="0 0 0" rpy="0 0 0"/>
    <mass value="0.125"/>
    <inertia ixx="0.001"  ixy="0"  ixz="0" iyy="0.001" iyz="0" izz="0.001" />
  </inertial>

  <collision>
    <origin xyz="0 0 0" rpy="0 0 0"/>
    <geometry>
       <cylinder radius="0.0508" length="0.055"/>
    </geometry>
  </collision>

  <visual>
    <origin xyz="0 0 0" rpy="0 0 0"/>
    <geometry>
       <cylinder radius="0.0508" length="0.055"/>
    </geometry>
  </visual>
</link>

<joint name="lidar_joint" type="fixed">
  <parent link="base_link"/>
  <child link="lidar_link"/>
  <origin xyz="0 0 0.15" rpy="0 0 0"/>
</joint>

<link name="imu_link">
  <collision>
    <origin xyz="0 0 0" rpy="0 0 0"/>
    <geometry>
        <box size="0.02 0.02 0.02"/>
    </geometry>
  </collision>
  <visual>
    <origin xyz="0 0 0" rpy="0 0 0"/>
      <geometry>
        <box size="0.02 0.02 0.02"/>
      </geometry>
    <material name="silver"/>
  </visual>
    <inertial>
      <mass value="0.001" />
      <origin xyz="0 0 0" rpy="0 0 0"/>
      <inertia ixx="0.00000015" ixy="0" ixz="0" iyy="0.00000015" iyz="0" izz="0.00000015" />
    </inertial>
</link>
    
<joint name="imu_sensor_joint" type="fixed">
  <parent link="base_link"/>
  <child link="imu_link"/>
  <origin xyz="0.0 0.0 0.0" rpy="0 0 0"/>
</joint>


</robot>