<?xml version="1.0" ?>
<robot name="diff_bot" xmlns:xacro="http://www.ros.org/wiki/xacro">

<xacro:include filename="$(find diff_bot_description)/urdf/materials.xacro" />
<!--<xacro:include filename="$(find diff_bot_description)/urdf/diff_bot.trans" /> -->
<xacro:include filename="$(find diff_bot_description)/urdf/diff_bot.gazebo" /> 

<!--<link name="base_footprint"/>-->

<link name="base_link">
  <inertial>
    <origin xyz="0.0003705884700577632 1.0604832058231093e-13 0.034681404539174294" rpy="0 0 0"/>
    <mass value="111.46600539799809"/>
    <inertia ixx="1.550497" iyy="2.385555" izz="3.842836" ixy="0.0" iyz="0.0" ixz="-0.00534"/>
  </inertial>
  <visual>
    <origin xyz="0 0 0" rpy="0 0 0"/>
    <geometry>
      <mesh filename="file://$(find diff_bot_description)/meshes/base_link.stl" scale="0.001 0.001 0.001"/>
    </geometry>
    <material name="silver"/>
  </visual>
  <collision>
    <origin xyz="0 0 0" rpy="0 0 0"/>
    <geometry>
      <mesh filename="file://$(find diff_bot_description)/meshes/base_link.stl" scale="0.001 0.001 0.001"/>
    </geometry>
  </collision>
</link>

<link name="right_wheel_1">
  <inertial>
    <origin xyz="1.6006640457533194e-13 -0.014999999999999986 0.0" rpy="0 0 0"/>
    <mass value="3.8656904903340568"/>
    <inertia ixx="0.006113" iyy="0.011645" izz="0.006113" ixy="0.0" iyz="0.0" ixz="-0.0"/>
  </inertial>
  <visual>
    <origin xyz="-0.2 -0.24 -0.035" rpy="0 0 0"/>
    <geometry>
      <mesh filename="file://$(find diff_bot_description)/meshes/right_wheel_1.stl" scale="0.001 0.001 0.001"/>
    </geometry>
    <material name="silver"/>
  </visual>
  <collision>
    <origin xyz="-0.2 -0.24 -0.035" rpy="0 0 0"/>
    <geometry>
      <mesh filename="file://$(find diff_bot_description)/meshes/right_wheel_1.stl" scale="0.001 0.001 0.001"/>
    </geometry>
  </collision>
</link>

<link name="left_wheel_1">
  <inertial>
    <origin xyz="1.6006640457533194e-13 0.014999999999999986 0.0" rpy="0 0 0"/>
    <mass value="3.8656904903340568"/>
    <inertia ixx="0.006113" iyy="0.011645" izz="0.006113" ixy="-0.0" iyz="0.0" ixz="-0.0"/>
  </inertial>
  <visual>
    <origin xyz="-0.2 0.24 -0.035" rpy="0 0 0"/>
    <geometry>
      <mesh filename="file://$(find diff_bot_description)/meshes/left_wheel_1.stl" scale="0.001 0.001 0.001"/>
    </geometry>
    <material name="silver"/>
  </visual>
  <collision>
    <origin xyz="-0.2 0.24 -0.035" rpy="0 0 0"/>
    <geometry>
      <mesh filename="file://$(find diff_bot_description)/meshes/left_wheel_1.stl" scale="0.001 0.001 0.001"/>
    </geometry>
  </collision>
</link>

<!--<joint name="fixed" type="fixed">
  <origin xyz="0 0 0" rpy="0 0 0"/>
  <parent link="base_footprint"/>
  <child link="base_link"/>
</joint> -->

<joint name="right_wheel_joint" type="continuous">
  <origin xyz="0.2 0.24 0.035" rpy="0 0 0"/>
  <parent link="base_link"/>
  <child link="right_wheel_1"/>
  <axis xyz="0.0 1.0 0.0"/>
</joint>

<joint name="left_wheel_joint" type="continuous">
  <origin xyz="0.2 -0.24 0.035" rpy="0 0 0"/>
  <parent link="base_link"/>
  <child link="left_wheel_1"/>
  <axis xyz="0.0 1.0 0.0"/>
</joint>

<ros2_control name="GazeboSystem" type="system">
  <hardware>
    <plugin>gazebo_ros2_control/GazeboSystem</plugin>
  </hardware>
  <joint name="left_wheel_joint">
    <command_interface name="velocity"/>
    <state_interface name="position"/>
    <state_interface name="velocity"/>
  </joint>
    <joint name="right_wheel_joint">
    <command_interface name="velocity"/>
    <state_interface name="position"/>
    <state_interface name="velocity"/>
  </joint>
</ros2_control>

<gazebo>
  <plugin filename="libgazebo_ros2_control.so" name="gazebo_ros2_control">
    <parameters>$(find diff_bot_description)/config/robot_controller.yaml</parameters>
  </plugin>
</gazebo>


 <!--setting up LIDAR sensor  -->
<link name="lidar_link">
  <inertial>
    <origin xyz="0 0 0" rpy="0 0 0"/>
    <mass value="0.125"/>
    <inertia ixx="0.001"  ixy="0"  ixz="0" iyy="0.001" iyz="0" izz="0.001" />
  </inertial>

  <collision>
    <origin xyz="0 0 0" rpy="0 0 0"/>
    <geometry>
       <cylinder radius="0.0508" length="0.055"/>
    </geometry>
  </collision>

  <visual>
    <origin xyz="0 0 0" rpy="0 0 0"/>
    <geometry>
       <cylinder radius="0.0508" length="0.055"/>
    </geometry>
  </visual>
</link>

<joint name="lidar_joint" type="fixed">
  <parent link="base_link"/>
  <child link="lidar_link"/>
  <origin xyz="0 0 0.15" rpy="0 0 0"/>
</joint>

<gazebo reference="lidar_link">
  <sensor name="lidar" type="ray">
    <always_on>true</always_on>
    <visualize>true</visualize>
    <update_rate>5</update_rate>
    <ray>
      <scan>
        <horizontal>
          <samples>360</samples>
          <resolution>1.000000</resolution>
          <min_angle>0.000000</min_angle>
          <max_angle>6.280000</max_angle>
        </horizontal>
      </scan>
      <range>
        <min>0.120000</min>
        <max>3.5</max>
        <resolution>0.015000</resolution>
      </range>
      <noise>
        <type>gaussian</type>
        <mean>0.0</mean>
        <stddev>0.01</stddev>
      </noise>
    </ray>
    <plugin name="scan" filename="libgazebo_ros_ray_sensor.so">
      <ros>
        <remapping>~/out:=laser_scan</remapping>
      </ros>
      <output_type>sensor_msgs/LaserScan</output_type>
      <frame_name>lidar_link</frame_name>
    </plugin>
  </sensor>
</gazebo>

<!--       setting up IMU                 -->
<link name="imu_sensor_link">
  <collision>
    <origin xyz="0 0 0" rpy="0 0 0"/>
    <geometry>
        <box size="0.02 0.02 0.02"/>
    </geometry>
  </collision>
  <visual>
    <origin xyz="0 0 0" rpy="0 0 0"/>
      <geometry>
        <box size="0.02 0.02 0.02"/>
      </geometry>
    <material name="silver"/>
  </visual>
    <inertial>
      <mass value="0.001" />
      <origin xyz="0 0 0" rpy="0 0 0"/>
      <inertia ixx="0.00000015" ixy="0" ixz="0" iyy="0.00000015" iyz="0" izz="0.00000015" />
    </inertial>
</link>
    
<joint name="imu_sensor_joint" type="fixed">
  <parent link="base_link"/>
  <child link="imu_sensor_link"/>
  <origin xyz="0.26 0.0 0.07" rpy="0 0 0"/>
</joint>


<gazebo reference="imu_sensor_link">
  <gravity>true</gravity>
  <sensor name='imu_sensor' type='imu'>
    <always_on>1</always_on>
    <update_rate>100</update_rate>
    <visualize>1</visualize>
    <topic>__default_topic__</topic>
    <plugin name='imu' filename='libgazebo_ros_imu_sensor.so'>
      <topicName>imu</topicName>
      <ros>
        <remapping>~/out:=imu_data</remapping>
      </ros>
      <bodyName>imu_sensor_link</bodyName>
      <updateRateHZ>100.0</updateRateHZ>
      <gaussianNoise>0.0</gaussianNoise>
      <xyzOffset>0 0 0</xyzOffset>
      <rpyOffset>0 0 0</rpyOffset>
    </plugin>
    <pose>0 0 0 0 0 0</pose>
  </sensor>
</gazebo>

</robot>